Workbook

Sheet Summary
A1: Build cost summary
A3: Section | B3: Budget | C3: Actual paid
A4: Doors & windows | B4: =SUMIFS(Materials!$F$5:$F$77,Materials!$A$5:$A$77,$A4) -> 670 | C4: =SUMIFS(Materials!$G$5:$G$77,Materials!$A$5:$A$77,$A4) -> 0
A5: False wall (bolt-in) | B5: =SUMIFS(Materials!$F$5:$F$77,Materials!$A$5:$A$77,$A5) -> 280 | C5: =SUMIFS(Materials!$G$5:$G$77,Materials!$A$5:$A$77,$A5) -> 0
A6: Ramp deck | B6: =SUMIFS(Materials!$F$5:$F$77,Materials!$A$5:$A$77,$A6) -> 330 | C6: =SUMIFS(Materials!$G$5:$G$77,Materials!$A$5:$A$77,$A6) -> 0
A7: Insulation & finish | B7: =SUMIFS(Materials!$F$5:$F$77,Materials!$A$5:$A$77,$A7) -> 720 | C7: =SUMIFS(Materials!$G$5:$G$77,Materials!$A$5:$A$77,$A7) -> 0
A8: E-track & bed | B8: =SUMIFS(Materials!$F$5:$F$77,Materials!$A$5:$A$77,$A8) -> 884 | C8: =SUMIFS(Materials!$G$5:$G$77,Materials!$A$5:$A$77,$A8) -> 0
A9: Climate & safety | B9: =SUMIFS(Materials!$F$5:$F$77,Materials!$A$5:$A$77,$A9) -> 1531 | C9: =SUMIFS(Materials!$G$5:$G$77,Materials!$A$5:$A$77,$A9) -> 0
A10: Electrical & solar | B10: =SUMIFS(Materials!$F$5:$F$77,Materials!$A$5:$A$77,$A10) -> 1412 | C10: =SUMIFS(Materials!$G$5:$G$77,Materials!$A$5:$A$77,$A10) -> 0
A11: Tongue battery box | B11: =SUMIFS(Materials!$F$5:$F$77,Materials!$A$5:$A$77,$A11) -> 50 | C11: =SUMIFS(Materials!$G$5:$G$77,Materials!$A$5:$A$77,$A11) -> 0
A12: Wash corner | B12: =SUMIFS(Materials!$F$5:$F$77,Materials!$A$5:$A$77,$A12) -> 525 | C12: =SUMIFS(Materials!$G$5:$G$77,Materials!$A$5:$A$77,$A12) -> 0
A13: Outdoor kitchen | B13: =SUMIFS(Materials!$F$5:$F$77,Materials!$A$5:$A$77,$A13) -> 60 | C13: =SUMIFS(Materials!$G$5:$G$77,Materials!$A$5:$A$77,$A13) -> 0
A14: Optional off-road | B14: =SUMIFS(Materials!$F$5:$F$77,Materials!$A$5:$A$77,$A14) -> 600 | C14: =SUMIFS(Materials!$G$5:$G$77,Materials!$A$5:$A$77,$A14) -> 0
A15: Total, all items | B15: =SUM(B4:B14) -> 7062 | C15: =SUM(C4:C14) -> 0
A16: Total without optional off-road | B16: =B15-B14 -> 6462 | C16: =C15-C14 -> 0
A18: Listed prices: rooftop AC, battery, converter/charger, toilet. Everything else is Claude's rough estimate, not a quote.

Sheet Materials
A1: 5x10 cargo camper build - materials list
A2: How to use: blue numbers are the budget (rough estimates unless a source is noted) - edit them freely. Enter what you actually pay in the yellow 'Actual paid' column (example: 615 for the door). Totals update automatically.
A4: Section | B4: Item | C4: Qty | D4: Unit | E4: Budget each | F4: Budget total | G4: Actual paid | H4: Notes / source
A5: Doors & windows | B5: Door for false wall, ~24 in wide, under 60 in tall (used/eBay/salvage) | C5: 1 | D5: ea | E5: 150 | F5: =C5*E5 -> 150 | H5: New Challenger 805 26x36 lists ~$615-953 (elkhartrvparts.com); match wall-thickness range, right hinge
A6: Doors & windows | B6: Window for false wall, ~24x18 with screen (used/eBay) | C6: 1 | D6: ea | E6: 50 | F6: =C6*E6 -> 50 | H6: Set bottom above the 34 in sink counter
A7: Doors & windows | B7: RV side windows ~24x15 with screens (used/eBay) | C7: 4 | D7: ea | E7: 50 | F7: =C7*E7 -> 200 | H7: New EZ Lite 23x14 is $159.95 (walmart.com); size one for egress
A8: Doors & windows | B8: Front window ~36x15-18, acrylic/polycarbonate (used/eBay) | C8: 1 | D8: ea | E8: 60 | F8: =C8*E8 -> 60 | H8: High and centered, 38-52 in off floor
A9: Doors & windows | B9: Removable front rock guard | C9: 1 | D9: ea | E9: 40 | F9: =C9*E9 -> 40 | H9: Bolt on for travel
A10: Doors & windows | B10: Window framing tube + rivet nuts | C10: 1 | D10: lot | E10: 60 | F10: =C10*E10 -> 60 | H10: 5 openings between wall posts
A11: Doors & windows | B11: Skylight, ~14x22 in, dome + interior trim (eBay) | C11: 1 | D11: ea | E11: 30 | F11: =C11*E11 -> 30 | H11: Rear of roof, over entry
A12: Doors & windows | B12: Butyl tape + self-leveling lap sealant | C12: 1 | D12: lot | E12: 50 | F12: =C12*E12 -> 50 | H12: Every roof/wall penetration
A13: Doors & windows | B13: Reflective window shades | C13: 1 | D13: lot | E13: 30 | F13: =C13*E13 -> 30
A14: False wall (bolt-in) | B14: Steel tube to match trailer frame | C14: 40 | D14: ft | E14: 2 | F14: =C14*E14 -> 80 | H14: Perimeter, door, window and heater-port openings
A15: False wall (bolt-in) | B15: Bolt-on tabs, grade 8 bolts, rivet nuts | C15: 1 | D15: lot | E15: 40 | F15: =C15*E15 -> 40 | H15: Removable for hauling
A16: False wall (bolt-in) | B16: Wall skins: aluminum/FRP outside + interior panel | C16: 1 | D16: lot | E16: 60 | F16: =C16*E16 -> 60
A17: False wall (bolt-in) | B17: 3/4-1 in polyiso foam for wall cavities | C17: 1 | D17: sheet | E17: 25 | F17: =C17*E17 -> 25
A18: False wall (bolt-in) | B18: Perimeter gasket/seal + drip edge | C18: 1 | D18: lot | E18: 30 | F18: =C18*E18 -> 30
A19: False wall (bolt-in) | B19: Heater duct port (~3 in, capped) | C19: 1 | D19: ea | E19: 15 | F19: =C19*E19 -> 15 | H19: Low center section, between window and door
A20: False wall (bolt-in) | B20: Exterior weatherproof 12V outlet + plug-in connector | C20: 1 | D20: set | E20: 30 | F20: =C20*E20 -> 30 | H20: Powers the portable diesel heater; wall stays removable
A21: Ramp deck | B21: Adjustable support legs / jack stands for ramp | C21: 2 | D21: ea | E21: 25 | F21: =C21*E21 -> 50
A22: Ramp deck | B22: Interlocking deck tiles or outdoor rug, 5x5 ft | C22: 1 | D22: lot | E22: 40 | F22: =C22*E22 -> 40
A23: Ramp deck | B23: Removable railing + step | C23: 1 | D23: set | E23: 80 | F23: =C23*E23 -> 80
A24: Ramp deck | B24: Two folding camp chairs | C24: 2 | D24: ea | E24: 30 | F24: =C24*E24 -> 60
A25: Ramp deck | B25: Rear awning + keder rail on rear header | C25: 1 | D25: set | E25: 100 | F25: =C25*E25 -> 100 | H25: Covers deck and door
A26: Insulation & finish | B26: 1 in polyiso foam board, 4x8 | C26: 8 | D26: sheet | E26: 25 | F26: =C26*E26 -> 200 | H26: Walls, ceiling, front wall
A27: Insulation & finish | B27: Reflectix + foil tape | C27: 1 | D27: roll | E27: 40 | F27: =C27*E27 -> 40
A28: Insulation & finish | B28: Wall/ceiling paneling, 1/4 in plywood or FRP, 4x8 | C28: 8 | D28: sheet | E28: 30 | F28: =C28*E28 -> 240
A29: Insulation & finish | B29: Floor insulation + vinyl or rubber flooring | C29: 1 | D29: lot | E29: 100 | F29: =C29*E29 -> 100 | H29: Washable for hauling
A30: Insulation & finish | B30: 3/4 in plywood backer strips for E-track | C30: 2 | D30: sheet | E30: 50 | F30: =C30*E30 -> 100
A31: Insulation & finish | B31: White reflective roof coating | C31: 1 | D31: gal | E31: 40 | F31: =C31*E31 -> 40 | H31: Biggest summer heat gain is the roof
A32: E-track & bed | B32: Horizontal E-track, 5 ft sections | C32: 14 | D32: ea | E32: 18 | F32: =C32*E32 -> 252 | H32: 3 rows x 2 walls + front wall
A33: E-track & bed | B33: Vertical E-track strips (adjustable desk height) | C33: 4 | D33: ea | E33: 15 | F33: =C33*E33 -> 60
A34: E-track & bed | B34: E-track 2x4 beam sockets | C34: 12 | D34: ea | E34: 6 | F34: =C34*E34 -> 72 | H34: Bed at ~10 in, desk at ~30-32 in
A35: E-track & bed | B35: E-track single-stud fittings + shelf brackets | C35: 1 | D35: lot | E35: 50 | F35: =C35*E35 -> 50
A36: E-track & bed | B36: 2x4 lumber for beams | C36: 6 | D36: ea | E36: 5 | F36: =C36*E36 -> 30
A37: E-track & bed | B37: Plywood for bed/desk panels (3 panels ~57x24) | C37: 2 | D37: sheet | E37: 45 | F37: =C37*E37 -> 90
A38: E-track & bed | B38: Laminate top for desk panel | C38: 1 | D38: ea | E38: 30 | F38: =C38*E38 -> 30
A39: E-track & bed | B39: Tri-fold mattress, full (54x75), 6 in | C39: 1 | D39: ea | E39: 150 | F39: =C39*E39 -> 150
A40: E-track & bed | B40: Ventilated mattress underlay | C40: 1 | D40: ea | E40: 50 | F40: =C40*E40 -> 50
A41: E-track & bed | B41: High shelves / cabinet materials | C41: 1 | D41: lot | E41: 100 | F41: =C41*E41 -> 100
...
